Workbook

Sheet Cadastro de Cliente
A1: FORMULÁRIO DE CADASTRO DE DADOS
A2: Informações da obra | W2: Controle
A3: Cliente | D3: VMIX CONCRETO LTDA
A4: Obra | D4: VMIX CONCRETO
A5: Local | D5: RONDONÓPOLIS-MT
A6: ESTUDO DE DOSAGEM CARTAS BASE SEM PRÉ REQUISITOS ADICIONAIS USO EM EQUIPAMENTOS DE EXTRUSÃO.

Sheet Cadastro de Insumos
A2: Definições dos materiais
R3: =IF(COUNTIF(R4:R89,"ERRO")=0,IF(S3>=2,0,""),COUNTIF(R4:R89,"ERRO")) -> 0 | S3: =COUNTIF(R4:R89,"OK") -> 4 | T3: =IF(OR(R4=0,R18=0,R32=0)=TRUE,"ERRO","OK") -> OK | U3: =IF(R3<>0,"ERRO",IF(S3<3,"ERRO",IF(T3="ERRO","ERRO","OK"))) -> OK
A4: Caracteristicas dos Cimentos | P4: Percentual | R4: =COUNTIF(R6:R16,"OK") -> 1
A5: Cimento Portland
A6: Tipo | E6: CP II F 40 | O6: TRUE | P6: 1 | R6: =IF(AND(O6=FALSE,E6="",E7="",E8="")=TRUE,"",IF(AND(O6=TRUE,E6<>"",E7<>"",E8<>"")=TRUE,"OK","ERRO")) -> OK
A7: Fabricante | E7: Votorantim
A8: Origem | E8: Cuiabá-MT
A9: Material Cimentício Suplementar 01
A10: Tipo | O10: FALSE | R10: =IF(AND(O10=FALSE,E10="",E11="",E12="")=TRUE,"",IF(AND(O10=TRUE,E10<>"",E11<>"",E12<>"")=TRUE,"OK","ERRO"))
A11: Fabricante
A12: Origem
A13: Material Cimentício Suplementar 02
A14: Tipo | O14: FALSE | R14: =IF(AND(O14=FALSE,E14="",E15="",E16="")=TRUE,"",IF(AND(O14=TRUE,E14<>"",E15<>"",E16<>"")=TRUE,"OK","ERRO"))
A15: Fabricante
A16: Origem
A18: Caracteristicas dos Agregados Miúdos | R18: =COUNTIF(R20:R30,"OK") -> 1
A19: Agregado01
A20: Tipo | E20: Areia Natural do Rio Cuiabá | O20: TRUE | P20: 0.7 | R20: =IF(AND(O20=FALSE,E20="",E21="",E22="")=TRUE,"",IF(AND(O20=TRUE,E20<>"",E21<>"",E22<>"")=TRUE,"OK","ERRO")) -> OK
A21: Fornecedor | E21: -
A22: Origem | E22: Cuiabá - MT
A23: Agregado 02
A24: Tipo | O24: FALSE | R24: =IF(AND(O24=FALSE,E24="",E25="",E26="")=TRUE,"",IF(AND(O24=TRUE,E24<>"",E25<>"",E26<>"")=TRUE,"OK","ERRO"))
A25: Fornecedor
A26: Origem
A27: Agregado 03
A28: Tipo | O28: FALSE | R28: =IF(AND(O28=FALSE,E28="",E29="",E30="")=TRUE,"",IF(AND(O28=TRUE,E28<>"",E29<>"",E30<>"")=TRUE,"OK","ERRO"))
A29: Fornecedor
A30: Origem
A32: Caracteristicas dos Agregados Graúdos | R32: =COUNTIF(R34:R44,"OK") -> 2
A33: Agregado 01
A34: Tipo | E34: Brita 1 | O34: TRUE | P34: 0.6 | R34: =IF(AND(O34=FALSE,E34="",E35="",E36="")=TRUE,"",IF(AND(O34=TRUE,E34<>"",E35<>"",E36<>"")=TRUE,"OK","ERRO")) -> OK
A35: Fornecedor | E35: Serra de São Vicente
A36: Origem | E36: Cuiabá-MT
A37: Agregado 02
A38: Tipo | E38: Brita 0 | O38: TRUE | P38: 0.4 | R38: =IF(AND(O38=FALSE,E38="",E39="",E40="")=TRUE,"",IF(AND(O38=TRUE,E38<>"",E39<>"",E40<>"")=TRUE,"OK","ERRO")) -> OK
A39: Fornecedor | E39: Serra de São Vicente
A40: Origem | E40: Cuiabá-MT
A41: Agregado 03
A42: Tipo | R42: =IF(AND(O42=FALSE,E42="",E43="",E44="")=TRUE,"",IF(AND(O42=TRUE,E42<>"",E43<>"",E44<>"")=TRUE,"OK","ERRO"))
A43: Fornecedor
...

Sheet Escopo de Estudo
A2: Critérios do Estudos de Dosagem
A3: Slump: | D3: 120 | F3: FALSE | I3: TRUE | L3: FALSE | O3: =IF(D3<>"",1,0) -> 1 | P3: =IF(F3=TRUE,1,0) -> 0 | Q3: =IF(I3=TRUE,1,0) -> 1 | R3: =IF(L3=TRUE,1,0) -> 0 | S3: =SUM(P3:R3) -> 1 | T3: =IF(AND(S3=1,O3=1,AG8="OK")=TRUE,"OK","ERRO") -> OK
A7: Valor de "m" | D7: Traço A | H7: Traço B | L7: Traço C | P7: Traço D | T7: Traço E | X7: Traço F | AB7: Traço G
D8: 3 | G8: =IF(AND(D8<>"",D10=TRUE)=TRUE,1,0) -> 1 | H8: 4 | K8: =IF(AND(H8<>"",H10=TRUE)=TRUE,1,0) -> 1 | L8: 5 | O8: =IF(AND(L8<>"",L10=TRUE)=TRUE,1,0) -> 1 | P8: 6 | S8: =IF(AND(P8<>"",P10=TRUE)=TRUE,1,0) -> 1 | T8: 7 | W8: =IF(AND(T8<>"",T10=TRUE)=TRUE,1,0) -> 1 | X8: 8 | AA8: =IF(AND(X8<>"",X10=TRUE)=TRUE,1,0) -> 1 | AB8: 9 | AE8: =IF(AND(AB8<>"",AB10=TRUE)=TRUE,1,0) -> 1 | AF8: =AE8+AA8+W8+S8+O8+K8+G8 -> 7 | AG8: =IF(OR(T15="ERRO",T19="ERRO",T23="ERRO",T27="ERRO")*TRUE,"ERRO",IF(AF8<3,"ERRO",IF(OR((AF8-AF9)<>1,AF10<>G9)=TRUE,"ERRO","OK"))) -> OK
G9: =IF(OR(D10=FALSE,H10=FALSE)=TRUE,"",IF(OR(D8="",H8="")=TRUE,"",IF((H8-D8)<0,0,H8-D8))) -> 1 | K9: =IF(OR(H10=FALSE,L10=FALSE)=TRUE,"",IF(OR(H8="",L8="")=TRUE,"",IF((L8-H8)<0,0,L8-H8))) -> 1 | O9: =IF(OR(L10=FALSE,P10=FALSE)=TRUE,"",IF(OR(L8="",P8="")=TRUE,"",IF((P8-L8)<0,0,P8-L8))) -> 1 | S9: =IF(OR(P10=FALSE,T10=FALSE)=TRUE,"",IF(OR(P8="",T8="")=TRUE,"",IF((T8-P8)<0,0,T8-P8))) -> 1 | W9: =IF(OR(T10=FALSE,X10=FALSE)=TRUE,"",IF(OR(T8="",X8="")=TRUE,"",IF((X8-T8)<0,0,X8-T8))) -> 1 | AA9: =IF(OR(X10=FALSE,AB10=FALSE)=TRUE,"",IF(OR(X8="",AB8="")=TRUE,"",IF((AB8-X8)<0,0,AB8-X8))) -> 1 | AF9: =COUNT(AE9,AA9,W9,S9,O9,K9,G9) -> 6
D10: TRUE | H10: TRUE | L10: TRUE | P10: TRUE | T10: TRUE | X10: TRUE | AB10: TRUE | AF10: =AVERAGE(AE9,AA9,W9,S9,O9,K9,G9) -> 1
A14: Classe de Agressividade | D14: FALSE | G14: FALSE | J14: FALSE | M14: FALSE | P14: TRUE | T14: =COUNTIF(D14:R16,TRUE) -> 1
T15: =IF(T14<>1,"ERRO","OK") -> OK
A18: Local de Aplicação | D18: FALSE | H18: FALSE | L18: TRUE | T18: =COUNTIF(D18:N20,TRUE) -> 1
T19: =IF(T18<>1,"ERRO","OK") -> OK
A22: Tipo de Aplicação | D22: FALSE | H22: TRUE | L22: FALSE | P22: FALSE | T22: =COUNTIF(D22:R24,TRUE) -> 1
T23: =IF(T22<>1,"ERRO","OK") -> OK
A26: Idades | D26: TRUE | H26: FALSE | L26: FALSE | P26: FALSE | T26: =COUNTIF(D26:Q28,TRUE) -> 1
T27: =IF(T26<>1,"ERRO","OK") -> OK
A30: Inicial de Agregados Graúdos (kg) | D30: 20 | G30: Argamassa Inicial (%) | J30: 0.51
A36: Idade Avaliada | D36: 28 | G36: Tipo de CP Avaliado | J36: 10x20 Axial

Sheet Dados - Fase Plástica
A1: Dados da Fase Plástica | J1: =IF(SUM(J4:J24)>0,"ERRO","OK") -> OK | M1: ='Escopo de Estudo'!AG8 -> OK | N1: ='Cadastro de Insumos'!U3 -> OK | P1: =IF(OR(M1="ERRO",N1="ERRO")=TRUE,"ERRO","OK") -> OK
A4: =IF('Escopo de Estudo'!AG8="OK",IF('Escopo de Estudo'!D10=TRUE,"Traço A: m = "&'Escopo de Estudo'!D8,"ERRO")) -> Traço A: m = 3 | I4: =IF(A4="ERRO",1,0) -> 0 | K4: britas | L4: cimento dosagem | M4: a/MC | N4: ME | O4: C Cimentos | P4: C Cim Portland
A5: α (%) | B5: 0.51 | C5: Água (kg) | D5: 3.48 | E5: Slump (mm) | F5: 200 | G5: Peso (kg) | H5: 19.58 | J5: =IF(I4=1,0,IF(OR(B5="",D5="",F5="",H5="")=TRUE,1,0)) -> 0 | K5: ='Escopo de Estudo'!$D$8-(B5*(1+'Escopo de Estudo'!$D$8)-1) -> 1.96 | L5: ='Escopo de Estudo'!$D$30/K5 -> 10.204082 | M5: =D5/L5 -> 0.34104 | N5: =(H5-$G$27)/$C$27 -> 2460.3774 | O5: =N5/(1+'Escopo de Estudo'!D8+M5) -> 566.77141 | P5: =O5*'Cadastro de Insumos'!$P$6 -> 566.77141
A7: =IF('Escopo de Estudo'!AG8="OK",IF('Escopo de Estudo'!H10=TRUE,"Traço B: m = "&'Escopo de Estudo'!H8,"ERRO")) -> Traço B: m = 4 | I7: =IF(A7="ERRO",1,0) -> 0
A8: α (%) | B8: 0.51 | C8: Água (kg) | D8: 3.5 | E8: Slump (mm) | F8: 200 | G8: Peso (kg) | H8: 19.58 | J8: =IF(I7=1,0,IF(OR(B8="",D8="",F8="",H8="")=TRUE,1,0)) -> 0 | K8: ='Escopo de Estudo'!H8-(B8*(1+'Escopo de Estudo'!H8)-1) -> 2.45 | L8: ='Escopo de Estudo'!$D$30/K8 -> 8.1632653 | M8: =D8/L8 -> 0.42875 | N8: =(H8-$G$27)/$C$27 -> 2460.3774 | O8: =N8/(1+'Escopo de Estudo'!H8+M8) -> 453.2125 | P8: =O8*'Cadastro de Insumos'!$P$6 -> 453.2125
A10: =IF('Escopo de Estudo'!AG8="OK",IF('Escopo de Estudo'!L10=TRUE,"Traço A: m = "&'Escopo de Estudo'!L8,"ERRO")) -> Traço A: m = 5 | I10: =IF(A10="ERRO",1,0) -> 0
A11: α (%) | B11: 0.51 | C11: Água (kg) | D11: 3.44 | E11: Slump (mm) | F11: 200 | G11: Peso (kg) | H11: 19.58 | J11: =IF(I10=1,0,IF(OR(B11="",D11="",F11="",H11="")=TRUE,1,0)) -> 0 | K11: ='Escopo de Estudo'!L8-(B11*(1+'Escopo de Estudo'!L8)-1) -> 2.94 | L11: ='Escopo de Estudo'!$D$30/K11 -> 6.8027211 | M11: =D11/L11 -> 0.50568 | N11: =(H11-$G$27)/$C$27 -> 2460.3774 | O11: =N11/(1+'Escopo de Estudo'!L8+M11) -> 378.18911 | P11: =O11*'Cadastro de Insumos'!$P$6 -> 378.18911
A13: =IF('Escopo de Estudo'!AG8="OK",IF('Escopo de Estudo'!P10=TRUE,"Traço A: m = "&'Escopo de Estudo'!P8,"ERRO")) -> Traço A: m = 6 | I13: =IF(A13="ERRO",1,0) -> 0
A14: α (%) | B14: 0.51 | C14: Água (kg) | D14: 3.5 | E14: Slump (mm) | F14: 200 | G14: Peso (kg) | H14: 19.58 | J14: =IF(I13=1,0,IF(OR(B14="",D14="",F14="",H14="")=TRUE,1,0)) -> 0 | K14: ='Escopo de Estudo'!P8-(B14*(1+'Escopo de Estudo'!P8)-1) -> 3.43 | L14: ='Escopo de Estudo'!$D$30/K14 -> 5.8309038 | M14: =D14/L14 -> 0.60025 | N14: =(H14-$G$27)/$C$27 -> 2460.3774 | O14: =N14/(1+'Escopo de Estudo'!P8+M14) -> 323.72321 | P14: =O14*'Cadastro de Insumos'!$P$6 -> 323.72321
A16: =IF('Escopo de Estudo'!AG8="OK",IF('Escopo de Estudo'!T10=TRUE,"Traço A: m = "&'Escopo de Estudo'!T8,"ERRO")) -> Traço A: m = 7 | I16: =IF(A16="ERRO",1,0) -> 0
A17: α (%) | B17: 0.51 | C17: Água (kg) | D17: 3.49 | E17: Slump (mm) | F17: 200 | G17: Peso (kg) | H17: 19.58 | J17: =IF(I16=1,0,IF(OR(B17="",D17="",F17="",H17="")=TRUE,1,0)) -> 0 | K17: ='Escopo de Estudo'!T8-(B17*(1+'Escopo de Estudo'!T8)-1) -> 3.92 | L17: ='Escopo de Estudo'!$D$30/K17 -> 5.1020408 | M17: =D17/L17 -> 0.68404 | N17: =(H17-$G$27)/$C$27 -> 2460.3774 | O17: =N17/(1+'Escopo de Estudo'!T8+M17) -> 283.32174 | P17: =O17*'Cadastro de Insumos'!$P$6 -> 283.32174
A19: =IF('Escopo de Estudo'!AG8="OK",IF('Escopo de Estudo'!X10=TRUE,"Traço A: m = "&'Escopo de Estudo'!X8,"ERRO")) -> Traço A: m = 8 | I19: =IF(A19="ERRO",1,0) -> 0
A20: α (%) | B20: 0.51 | C20: Água (kg) | D20: 3.5 | E20: Slump (mm) | F20: 200 | G20: Peso (kg) | H20: 19.58 | J20: =IF(I19=1,0,IF(OR(B20="",D20="",F20="",H20="")=TRUE,1,0)) -> 0 | K20: ='Escopo de Estudo'!X8-(B20*(1+'Escopo de Estudo'!X8)-1) -> 4.41 | L20: ='Escopo de Estudo'!$D$30/K20 -> 4.5351474 | M20: =D20/L20 -> 0.77175 | N20: =(H20-$G$27)/$C$27 -> 2460.3774 | O20: =N20/(1+'Escopo de Estudo'!X8+M20) -> 251.78472 | P20: =O20*'Cadastro de Insumos'!$P$6 -> 251.78472
A22: =IF('Escopo de Estudo'!AG8="OK",IF('Escopo de Estudo'!AB10=TRUE,"Traço A: m = "&'Escopo de Estudo'!AB8,"ERRO")) -> Traço A: m = 9 | I22: =IF(A22="ERRO",1,0) -> 0
A23: α (%) | B23: 0.51 | C23: Água (kg) | D23: 3.58 | E23: Slump (mm) | F23: 100 | G23: Peso (kg) | H23: 19.58 | J23: =IF(I22=1,0,IF(OR(B23="",D23="",F23="",H23="")=TRUE,1,0)) -> 0 | K23: ='Escopo de Estudo'!AB8-(B23*(1+'Escopo de Estudo'!AB8)-1) -> 4.9 | L23: ='Escopo de Estudo'!$D$30/K23 -> 4.0816327 | M23: =D23/L23 -> 0.8771 | N23: =(H23-$G$27)/$C$27 -> 2460.3774 | O23: =N23/(1+'Escopo de Estudo'!AB8+M23) -> 226.19792 | P23: =O23*'Cadastro de Insumos'!$P$6 -> 226.19792
A26: EQUIPAMENTOS PARA MASSA ESPECÍFICA
A27: Volume (m³) | C27: 0.0053 | E27: Tara (kg) | G27: 6.54

Sheet Dados - Resistências
A1: RESISTÊNCIAS | L1: {=_xlfn.UNIQUE(CPs[m])} -> 3
L2: 4 | T2: Tipo CP | U2: Ponderador | W2: Tipos de Ruptura
L3: 5 | T3: 10x20 Axial | U3: 1.2487 | W3: A
L4: 6 | T4: 10x20 Diametral | U4: 0.3183 | W4: B
A5: CP | B5: Tipo de CP | C5: m | D5: Data de Moldagem | E5: Idade | F5: Data de Ruptura | G5: Carga (tonelada) | H5: Tipo de Ruptura | I5: Fcj (MPa) | J5: Índice de Eficiência | L5: 7 | T5: 10x10x40 Flexão | U5: 0.0981 | W5: C
A6: 44580 | B6: 10x20 Axial | C6: 3 | D6: 45663 | E6: 7 | F6: =CPs[[#This Row],[Data de Moldagem]]+CPs[[#This Row],[Idade]] -> 45670 | G6: 47 | H6: B | I6: =IF(OR(CPs[[#This Row],[Tipo de CP]]="",CPs[[#This Row],[Carga (tonelada)]]="")=TRUE,"",CPs[[#This Row],[Carga (tonelada)]]*VLOOKUP(CPs[[#This Row],[Tipo de CP]],$T$3:$U$5,2,FALSE)) -> 58.6889 | J6: =IF(OR(CPs[[#This Row],[Idade]]<>'Escopo de Estudo'!$D$36,CPs[[#This Row],[Tipo de CP]]<>'Escopo de Estudo'!$J$36)=TRUE,"",IF(OR(CPs[[#This Row],[Fcj (MPa)]]="",CPs[[#This Row],[m]]="")=TRUE,"",VLOOKUP(CPs[[#This Row],[m]],'Compilado de Dados'!$B$7:$D$13,3,FALSE)/CPs[[#This Row],[Fcj (MPa)]])) | L6: 8 | W6: D
A7: 44581 | B7: 10x20 Axial | C7: 3 | D7: 45663 | E7: 7 | F7: =CPs[[#This Row],[Data de Moldagem]]+CPs[[#This Row],[Idade]] -> 45670 | G7: 47 | H7: A | I7: =IF(OR(CPs[[#This Row],[Tipo de CP]]="",CPs[[#This Row],[Carga (tonelada)]]="")=TRUE,"",CPs[[#This Row],[Carga (tonelada)]]*VLOOKUP(CPs[[#This Row],[Tipo de CP]],$T$3:$U$5,2,FALSE)) -> 58.6889 | J7: =IF(OR(CPs[[#This Row],[Idade]]<>'Escopo de Estudo'!$D$36,CPs[[#This Row],[Tipo de CP]]<>'Escopo de Estudo'!$J$36)=TRUE,"",IF(OR(CPs[[#This Row],[Fcj (MPa)]]="",CPs[[#This Row],[m]]="")=TRUE,"",VLOOKUP(CPs[[#This Row],[m]],'Compilado de Dados'!$B$7:$D$13,3,FALSE)/CPs[[#This Row],[Fcj (MPa)]])) | L7: 9 | W7: E
A8: 44582 | B8: 10x20 Axial | C8: 3 | D8: 45663 | E8: 28 | F8: =CPs[[#This Row],[Data de Moldagem]]+CPs[[#This Row],[Idade]] -> 45691 | G8: 53 | H8: B | I8: =IF(OR(CPs[[#This Row],[Tipo de CP]]="",CPs[[#This Row],[Carga (tonelada)]]="")=TRUE,"",CPs[[#This Row],[Carga (tonelada)]]*VLOOKUP(CPs[[#This Row],[Tipo de CP]],$T$3:$U$5,2,FALSE)) -> 66.1811 | J8: =IF(OR(CPs[[#This Row],[Idade]]<>'Escopo de Estudo'!$D$36,CPs[[#This Row],[Tipo de CP]]<>'Escopo de Estudo'!$J$36)=TRUE,"",IF(OR(CPs[[#This Row],[Fcj (MPa)]]="",CPs[[#This Row],[m]]="")=TRUE,"",VLOOKUP(CPs[[#This Row],[m]],'Compilado de Dados'!$B$7:$D$13,3,FALSE)/CPs[[#This Row],[Fcj (MPa)]])) -> 8.5639466 | W8: F
A9: 44583 | B9: 10x20 Axial | C9: 3 | D9: 45663 | E9: 28 | F9: =CPs[[#This Row],[Data de Moldagem]]+CPs[[#This Row],[Idade]] -> 45691 | G9: 53 | H9: C | I9: =IF(OR(CPs[[#This Row],[Tipo de CP]]="",CPs[[#This Row],[Carga (tonelada)]]="")=TRUE,"",CPs[[#This Row],[Carga (tonelada)]]*VLOOKUP(CPs[[#This Row],[Tipo de CP]],$T$3:$U$5,2,FALSE)) -> 66.1811 | J9: =IF(OR(CPs[[#This Row],[Idade]]<>'Escopo de Estudo'!$D$36,CPs[[#This Row],[Tipo de CP]]<>'Escopo de Estudo'!$J$36)=TRUE,"",IF(OR(CPs[[#This Row],[Fcj (MPa)]]="",CPs[[#This Row],[m]]="")=TRUE,"",VLOOKUP(CPs[[#This Row],[m]],'Compilado de Dados'!$B$7:$D$13,3,FALSE)/CPs[[#This Row],[Fcj (MPa)]])) -> 8.5639466 | L9: =COUNT(_xlfn.ANCHORARRAY(L1)) -> 7 | M9: =COUNTIFS(CPs[Idade],'Escopo de Estudo'!D36,CPs[Tipo de CP],'Escopo de Estudo'!J36) -> 14 | W9: G
A10: 44584 | B10: 10x20 Axial | C10: 4 | D10: 45663 | E10: 7 | F10: =CPs[[#This Row],[Data de Moldagem]]+CPs[[#This Row],[Idade]] -> 45670 | G10: 34 | H10: B | I10: =IF(OR(CPs[[#This Row],[Tipo de CP]]="",CPs[[#This Row],[Carga (tonelada)]]="")=TRUE,"",CPs[[#This Row],[Carga (tonelada)]]*VLOOKUP(CPs[[#This Row],[Tipo de CP]],$T$3:$U$5,2,FALSE)) -> 42.4558 | J10: =IF(OR(CPs[[#This Row],[Idade]]<>'Escopo de Estudo'!$D$36,CPs[[#This Row],[Tipo de CP]]<>'Escopo de Estudo'!$J$36)=TRUE,"",IF(OR(CPs[[#This Row],[Fcj (MPa)]]="",CPs[[#This Row],[m]]="")=TRUE,"",VLOOKUP(CPs[[#This Row],[m]],'Compilado de Dados'!$B$7:$D$13,3,FALSE)/CPs[[#This Row],[Fcj (MPa)]])) | W10: MD
A11: 44585 | B11: 10x20 Axial | C11: 4 | D11: 45663 | E11: 7 | F11: =CPs[[#This Row],[Data de Moldagem]]+CPs[[#This Row],[Idade]] -> 45670 | G11: 34 | H11: A | I11: =IF(OR(CPs[[#This Row],[Tipo de CP]]="",CPs[[#This Row],[Carga (tonelada)]]="")=TRUE,"",CPs[[#This Row],[Carga (tonelada)]]*VLOOKUP(CPs[[#This Row],[Tipo de CP]],$T$3:$U$5,2,FALSE)) -> 42.4558 | J11: =IF(OR(CPs[[#This Row],[Idade]]<>'Escopo de Estudo'!$D$36,CPs[[#This Row],[Tipo de CP]]<>'Escopo de Estudo'!$J$36)=TRUE,"",IF(OR(CPs[[#This Row],[Fcj (MPa)]]="",CPs[[#This Row],[m]]="")=TRUE,"",VLOOKUP(CPs[[#This Row],[m]],'Compilado de Dados'!$B$7:$D$13,3,FALSE)/CPs[[#This Row],[Fcj (MPa)]])) | L11: =IF(OR(L9<>'Compilado de Dados'!$B$4,M9=0)=TRUE,"ERRO","OK") -> OK | W11: CENTRAL
A12: 44586 | B12: 10x20 Axial | C12: 4 | D12: 45663 | E12: 28 | F12: =CPs[[#This Row],[Data de Moldagem]]+CPs[[#This Row],[Idade]] -> 45691 | G12: 40 | H12: B | I12: =IF(OR(CPs[[#This Row],[Tipo de CP]]="",CPs[[#This Row],[Carga (tonelada)]]="")=TRUE,"",CPs[[#This Row],[Carga (tonelada)]]*VLOOKUP(CPs[[#This Row],[Tipo de CP]],$T$3:$U$5,2,FALSE)) -> 49.948 | J12: =IF(OR(CPs[[#This Row],[Idade]]<>'Escopo de Estudo'!$D$36,CPs[[#This Row],[Tipo de CP]]<>'Escopo de Estudo'!$J$36)=TRUE,"",IF(OR(CPs[[#This Row],[Fcj (MPa)]]="",CPs[[#This Row],[m]]="")=TRUE,"",VLOOKUP(CPs[[#This Row],[m]],'Compilado de Dados'!$B$7:$D$13,3,FALSE)/CPs[[#This Row],[Fcj (MPa)]])) -> 9.0736866
A13: 44587 | B13: 10x20 Axial | C13: 4 | D13: 45663 | E13: 28 | F13: =CPs[[#This Row],[Data de Moldagem]]+CPs[[#This Row],[Idade]] -> 45691 | G13: 40 | H13: C | I13: =IF(OR(CPs[[#This Row],[Tipo de CP]]="",CPs[[#This Row],[Carga (tonelada)]]="")=TRUE,"",CPs[[#This Row],[Carga (tonelada)]]*VLOOKUP(CPs[[#This Row],[Tipo de CP]],$T$3:$U$5,2,FALSE)) -> 49.948 | J13: =IF(OR(CPs[[#This Row],[Idade]]<>'Escopo de Estudo'!$D$36,CPs[[#This Row],[Tipo de CP]]<>'Escopo de Estudo'!$J$36)=TRUE,"",IF(OR(CPs[[#This Row],[Fcj (MPa)]]="",CPs[[#This Row],[m]]="")=TRUE,"",VLOOKUP(CPs[[#This Row],[m]],'Compilado de Dados'!$B$7:$D$13,3,FALSE)/CPs[[#This Row],[Fcj (MPa)]])) -> 9.0736866
A14: 44588 | B14: 10x20 Axial | C14: 5 | D14: 45663 | E14: 7 | F14: =CPs[[#This Row],[Data de Moldagem]]+CPs[[#This Row],[Idade]] -> 45670 | G14: 28 | H14: B | I14: =IF(OR(CPs[[#This Row],[Tipo de CP]]="",CPs[[#This Row],[Carga (tonelada)]]="")=TRUE,"",CPs[[#This Row],[Carga (tonelada)]]*VLOOKUP(CPs[[#This Row],[Tipo de CP]],$T$3:$U$5,2,FALSE)) -> 34.9636 | J14: =IF(OR(CPs[[#This Row],[Idade]]<>'Escopo de Estudo'!$D$36,CPs[[#This Row],[Tipo de CP]]<>'Escopo de Estudo'!$J$36)=TRUE,"",IF(OR(CPs[[#This Row],[Fcj (MPa)]]="",CPs[[#This Row],[m]]="")=TRUE,"",VLOOKUP(CPs[[#This Row],[m]],'Compilado de Dados'!$B$7:$D$13,3,FALSE)/CPs[[#This Row],[Fcj (MPa)]]))
A15: 44589 | B15: 10x20 Axial | C15: 5 | D15: 45663 | E15: 7 | F15: =CPs[[#This Row],[Data de Moldagem]]+CPs[[#This Row],[Idade]] -> 45670 | G15: 28 | H15: A | I15: =IF(OR(CPs[[#This Row],[Tipo de CP]]="",CPs[[#This Row],[Carga (tonelada)]]="")=TRUE,"",CPs[[#This Row],[Carga (tonelada)]]*VLOOKUP(CPs[[#This Row],[Tipo de CP]],$T$3:$U$5,2,FALSE)) -> 34.9636 | J15: =IF(OR(CPs[[#This Row],[Idade]]<>'Escopo de Estudo'!$D$36,CPs[[#This Row],[Tipo de CP]]<>'Escopo de Estudo'!$J$36)=TRUE,"",IF(OR(CPs[[#This Row],[Fcj (MPa)]]="",CPs[[#This Row],[m]]="")=TRUE,"",VLOOKUP(CPs[[#This Row],[m]],'Compilado de Dados'!$B$7:$D$13,3,FALSE)/CPs[[#This Row],[Fcj (MPa)]]))
A16: 44590 | B16: 10x20 Axial | C16: 5 | D16: 45663 | E16: 28 | F16: =CPs[[#This Row],[Data de Moldagem]]+CPs[[#This Row],[Idade]] -> 45691 | G16: 36 | H16: B | I16: =IF(OR(CPs[[#This Row],[Tipo de CP]]="",CPs[[#This Row],[Carga (tonelada)]]="")=TRUE,"",CPs[[#This Row],[Carga (tonelada)]]*VLOOKUP(CPs[[#This Row],[Tipo de CP]],$T$3:$U$5,2,FALSE)) -> 44.9532 | J16: =IF(OR(CPs[[#This Row],[Idade]]<>'Escopo de Estudo'!$D$36,CPs[[#This Row],[Tipo de CP]]<>'Escopo de Estudo'!$J$36)=TRUE,"",IF(OR(CPs[[#This Row],[Fcj (MPa)]]="",CPs[[#This Row],[m]]="")=TRUE,"",VLOOKUP(CPs[[#This Row],[m]],'Compilado de Dados'!$B$7:$D$13,3,FALSE)/CPs[[#This Row],[Fcj (MPa)]])) -> 8.412952
A17: 44591 | B17: 10x20 Axial | C17: 5 | D17: 45663 | E17: 28 | F17: =CPs[[#This Row],[Data de Moldagem]]+CPs[[#This Row],[Idade]] -> 45691 | G17: 36 | H17: C | I17: =IF(OR(CPs[[#This Row],[Tipo de CP]]="",CPs[[#This Row],[Carga (tonelada)]]="")=TRUE,"",CPs[[#This Row],[Carga (tonelada)]]*VLOOKUP(CPs[[#This Row],[Tipo de CP]],$T$3:$U$5,2,FALSE)) -> 44.9532 | J17: =IF(OR(CPs[[#This Row],[Idade]]<>'Escopo de Estudo'!$D$36,CPs[[#This Row],[Tipo de CP]]<>'Escopo de Estudo'!$J$36)=TRUE,"",IF(OR(CPs[[#This Row],[Fcj (MPa)]]="",CPs[[#This Row],[m]]="")=TRUE,"",VLOOKUP(CPs[[#This Row],[m]],'Compilado de Dados'!$B$7:$D$13,3,FALSE)/CPs[[#This Row],[Fcj (MPa)]])) -> 8.412952
A18: 44592 | B18: 10x20 Axial | C18: 6 | D18: 45663 | E18: 7 | F18: =CPs[[#This Row],[Data de Moldagem]]+CPs[[#This Row],[Idade]] -> 45670 | G18: 21 | H18: B | I18: =IF(OR(CPs[[#This Row],[Tipo de CP]]="",CPs[[#This Row],[Carga (tonelada)]]="")=TRUE,"",CPs[[#This Row],[Carga (tonelada)]]*VLOOKUP(CPs[[#This Row],[Tipo de CP]],$T$3:$U$5,2,FALSE)) -> 26.2227 | J18: =IF(OR(CPs[[#This Row],[Idade]]<>'Escopo de Estudo'!$D$36,CPs[[#This Row],[Tipo de CP]]<>'Escopo de Estudo'!$J$36)=TRUE,"",IF(OR(CPs[[#This Row],[Fcj (MPa)]]="",CPs[[#This Row],[m]]="")=TRUE,"",VLOOKUP(CPs[[#This Row],[m]],'Compilado de Dados'!$B$7:$D$13,3,FALSE)/CPs[[#This Row],[Fcj (MPa)]]))
A19: 44593 | B19: 10x20 Axial | C19: 6 | D19: 45663 | E19: 7 | F19: =CPs[[#This Row],[Data de Moldagem]]+CPs[[#This Row],[Idade]] -> 45670 | G19: 21 | H19: A | I19: =IF(OR(CPs[[#This Row],[Tipo de CP]]="",CPs[[#This Row],[Carga (tonelada)]]="")=TRUE,"",CPs[[#This Row],[Carga (tonelada)]]*VLOOKUP(CPs[[#This Row],[Tipo de CP]],$T$3:$U$5,2,FALSE)) -> 26.2227 | J19: =IF(OR(CPs[[#This Row],[Idade]]<>'Escopo de Estudo'!$D$36,CPs[[#This Row],[Tipo de CP]]<>'Escopo de Estudo'!$J$36)=TRUE,"",IF(OR(CPs[[#This Row],[Fcj (MPa)]]="",CPs[[#This Row],[m]]="")=TRUE,"",VLOOKUP(CPs[[#This Row],[m]],'Compilado de Dados'!$B$7:$D$13,3,FALSE)/CPs[[#This Row],[Fcj (MPa)]]))
A20: 44594 | B20: 10x20 Axial | C20: 6 | D20: 45663 | E20: 28 | F20: =CPs[[#This Row],[Data de Moldagem]]+CPs[[#This Row],[Idade]] -> 45691 | G20: 24.71 | H20: B | I20: =IF(OR(CPs[[#This Row],[Tipo de CP]]="",CPs[[#This Row],[Carga (tonelada)]]="")=TRUE,"",CPs[[#This Row],[Carga (tonelada)]]*VLOOKUP(CPs[[#This Row],[Tipo de CP]],$T$3:$U$5,2,FALSE)) -> 30.855377 | J20: =IF(OR(CPs[[#This Row],[Idade]]<>'Escopo de Estudo'!$D$36,CPs[[#This Row],[Tipo de CP]]<>'Escopo de Estudo'!$J$36)=TRUE,"",IF(OR(CPs[[#This Row],[Fcj (MPa)]]="",CPs[[#This Row],[m]]="")=TRUE,"",VLOOKUP(CPs[[#This Row],[m]],'Compilado de Dados'!$B$7:$D$13,3,FALSE)/CPs[[#This Row],[Fcj (MPa)]])) -> 10.49163
A21: 44595 | B21: 10x20 Axial | C21: 6 | D21: 45663 | E21: 28 | F21: =CPs[[#This Row],[Data de Moldagem]]+CPs[[#This Row],[Idade]] -> 45691 | G21: 24.71 | H21: C | I21: =IF(OR(CPs[[#This Row],[Tipo de CP]]="",CPs[[#This Row],[Carga (tonelada)]]="")=TRUE,"",CPs[[#This Row],[Carga (tonelada)]]*VLOOKUP(CPs[[#This Row],[Tipo de CP]],$T$3:$U$5,2,FALSE)) -> 30.855377 | J21: =IF(OR(CPs[[#This Row],[Idade]]<>'Escopo de Estudo'!$D$36,CPs[[#This Row],[Tipo de CP]]<>'Escopo de Estudo'!$J$36)=TRUE,"",IF(OR(CPs[[#This Row],[Fcj (MPa)]]="",CPs[[#This Row],[m]]="")=TRUE,"",VLOOKUP(CPs[[#This Row],[m]],'Compilado de Dados'!$B$7:$D$13,3,FALSE)/CPs[[#This Row],[Fcj (MPa)]])) -> 10.49163
A22: 44596 | B22: 10x20 Axial | C22: 7 | D22: 45663 | E22: 7 | F22: =CPs[[#This Row],[Data de Moldagem]]+CPs[[#This Row],[Idade]] -> 45670 | G22: 18 | H22: B | I22: =IF(OR(CPs[[#This Row],[Tipo de CP]]="",CPs[[#This Row],[Carga (tonelada)]]="")=TRUE,"",CPs[[#This Row],[Carga (tonelada)]]*VLOOKUP(CPs[[#This Row],[Tipo de CP]],$T$3:$U$5,2,FALSE)) -> 22.4766 | J22: =IF(OR(CPs[[#This Row],[Idade]]<>'Escopo de Estudo'!$D$36,CPs[[#This Row],[Tipo de CP]]<>'Escopo de Estudo'!$J$36)=TRUE,"",IF(OR(CPs[[#This Row],[Fcj (MPa)]]="",CPs[[#This Row],[m]]="")=TRUE,"",VLOOKUP(CPs[[#This Row],[m]],'Compilado de Dados'!$B$7:$D$13,3,FALSE)/CPs[[#This Row],[Fcj (MPa)]]))
A23: 44597 | B23: 10x20 Axial | C23: 7 | D23: 45663 | E23: 7 | F23: =CPs[[#This Row],[Data de Moldagem]]+CPs[[#This Row],[Idade]] -> 45670 | G23: 18 | H23: A | I23: =IF(OR(CPs[[#This Row],[Tipo de CP]]="",CPs[[#This Row],[Carga (tonelada)]]="")=TRUE,"",CPs[[#This Row],[Carga (tonelada)]]*VLOOKUP(CPs[[#This Row],[Tipo de CP]],$T$3:$U$5,2,FALSE)) -> 22.4766 | J23: =IF(OR(CPs[[#This Row],[Idade]]<>'Escopo de Estudo'!$D$36,CPs[[#This Row],[Tipo de CP]]<>'Escopo de Estudo'!$J$36)=TRUE,"",IF(OR(CPs[[#This Row],[Fcj (MPa)]]="",CPs[[#This Row],[m]]="")=TRUE,"",VLOOKUP(CPs[[#This Row],[m]],'Compilado de Dados'!$B$7:$D$13,3,FALSE)/CPs[[#This Row],[Fcj (MPa)]]))
... A33: 44607 | B33: 10x20 Axial | C33: 9 | D33: 45663 | E33: 28 | F33: =CPs[[#This Row],[Data de Moldagem]]+CPs[[#This Row],[Idade]] -> 45691 | G33: 12 | H33: C | I33: =IF(OR(CPs[[#This Row],[Tipo de CP]]="",CPs[[#This Row],[Carga (tonelada)]]="")=TRUE,"",CPs[[#This Row],[Carga (tonelada)]]*VLOOKUP(CPs[[#This Row],[Tipo de CP]],$T$3:$U$5,2,FALSE)) -> 14.9844 | J33: =IF(OR(CPs[[#This Row],[Idade]]<>'Escopo de Estudo'!$D$36,CPs[[#This Row],[Tipo de CP]]<>'Escopo de Estudo'!$J$36)=TRUE,"",IF(OR(CPs[[#This Row],[Fcj (MPa)]]="",CPs[[#This Row],[m]]="")=TRUE,"",VLOOKUP(CPs[[#This Row],[m]],'Compilado de Dados'!$B$7:$D$13,3,FALSE)/CPs[[#This Row],[Fcj (MPa)]])) -> 15.09556

Sheet Avaliação de Resultado
B6: Resistência Desejada (MPa)
B7: 20

Sheet Compilado de Dados
B4: =COUNT(B7:B13) -> 7
A5: ID | B5: m | C5: a/c | D5: Consumo de Cimento Total | E5: Consumo de Cimento Portalnd | F5: Resistência Média | G5: Índice de Eficiência Média | H5: Slump de Ensaio
A7: 1 | B7: =IF('Escopo de Estudo'!AG8="OK",IF('Escopo de Estudo'!D10=TRUE,'Escopo de Estudo'!D8,"")) -> 3 | C7: =IF(B7="","",'Dados - Fase Plástica'!M5) -> 0.34104 | D7: =IF(B7="","",'Dados - Fase Plástica'!O5) -> 566.77141 | E7: =IF(B7="","",'Dados - Fase Plástica'!P5) -> 566.77141 | F7: =AVERAGEIFS(CPs[Fcj (MPa)],CPs[Idade],'Escopo de Estudo'!$D$36,CPs[Tipo de CP],'Escopo de Estudo'!$J$36,CPs[m],B7) -> 66.1811 | G7: =AVERAGEIFS(CPs[Índice de Eficiência],CPs[Idade],'Escopo de Estudo'!$D$36,CPs[Tipo de CP],'Escopo de Estudo'!$J$36,CPs[m],B7) -> 8.5639466 | H7: =IF(B7="","",'Dados - Fase Plástica'!F5) -> 200
A8: 2 | B8: =IF('Escopo de Estudo'!AG8="OK",IF('Escopo de Estudo'!H10=TRUE,'Escopo de Estudo'!H8,"")) -> 4 | C8: =IF(B8="","",'Dados - Fase Plástica'!M8) -> 0.42875 | D8: =IF(B8="","",'Dados - Fase Plástica'!O8) -> 453.2125 | E8: =IF(B8="","",'Dados - Fase Plástica'!P8) -> 453.2125 | F8: =AVERAGEIFS(CPs[Fcj (MPa)],CPs[Idade],'Escopo de Estudo'!$D$36,CPs[Tipo de CP],'Escopo de Estudo'!$J$36,CPs[m],B8) -> 49.948 | G8: =AVERAGEIFS(CPs[Índice de Eficiência],CPs[Idade],'Escopo de Estudo'!$D$36,CPs[Tipo de CP],'Escopo de Estudo'!$J$36,CPs[m],B8) -> 9.0736866 | H8: =IF(B8="","",'Dados - Fase Plástica'!F8) -> 200
A9: 3 | B9: =IF('Escopo de Estudo'!AG8="OK",IF('Escopo de Estudo'!L10=TRUE,'Escopo de Estudo'!L8,"")) -> 5 | C9: =IF(B9="","",'Dados - Fase Plástica'!M11) -> 0.50568 | D9: =IF(B9="","",'Dados - Fase Plástica'!O11) -> 378.18911 | E9: =IF(B9="","",'Dados - Fase Plástica'!P11) -> 378.18911 | F9: =AVERAGEIFS(CPs[Fcj (MPa)],CPs[Idade],'Escopo de Estudo'!$D$36,CPs[Tipo de CP],'Escopo de Estudo'!$J$36,CPs[m],B9) -> 44.9532 | G9: =AVERAGEIFS(CPs[Índice de Eficiência],CPs[Idade],'Escopo de Estudo'!$D$36,CPs[Tipo de CP],'Escopo de Estudo'!$J$36,CPs[m],B9) -> 8.412952 | H9: =IF(B9="","",'Dados - Fase Plástica'!F11) -> 200
A10: 4 | B10: =IF('Escopo de Estudo'!AG8="OK",IF('Escopo de Estudo'!P10=TRUE,'Escopo de Estudo'!P8,"")) -> 6 | C10: =IF(B10="","",'Dados - Fase Plástica'!M14) -> 0.60025 | D10: =IF(B10="","",'Dados - Fase Plástica'!O14) -> 323.72321 | E10: =IF(B10="","",'Dados - Fase Plástica'!P14) -> 323.72321 | F10: =AVERAGEIFS(CPs[Fcj (MPa)],CPs[Idade],'Escopo de Estudo'!$D$36,CPs[Tipo de CP],'Escopo de Estudo'!$J$36,CPs[m],B10) -> 30.855377 | G10: =AVERAGEIFS(CPs[Índice de Eficiência],CPs[Idade],'Escopo de Estudo'!$D$36,CPs[Tipo de CP],'Escopo de Estudo'!$J$36,CPs[m],B10) -> 10.49163 | H10: =IF(B10="","",'Dados - Fase Plástica'!F14) -> 200
A11: 5 | B11: =IF('Escopo de Estudo'!AG8="OK",IF('Escopo de Estudo'!T10=TRUE,'Escopo de Estudo'!T8,"")) -> 7 | C11: =IF(B11="","",'Dados - Fase Plástica'!M17) -> 0.68404 | D11: =IF(B11="","",'Dados - Fase Plástica'!O17) -> 283.32174 | E11: =IF(B11="","",'Dados - Fase Plástica'!P17) -> 283.32174 | F11: =AVERAGEIFS(CPs[Fcj (MPa)],CPs[Idade],'Escopo de Estudo'!$D$36,CPs[Tipo de CP],'Escopo de Estudo'!$J$36,CPs[m],B11) -> 26.2227 | G11: =AVERAGEIFS(CPs[Índice de Eficiência],CPs[Idade],'Escopo de Estudo'!$D$36,CPs[Tipo de CP],'Escopo de Estudo'!$J$36,CPs[m],B11) -> 10.804446 | H11: =IF(B11="","",'Dados - Fase Plástica'!F17) -> 200
A12: 6 | B12: =IF('Escopo de Estudo'!AG8="OK",IF('Escopo de Estudo'!X10=TRUE,'Escopo de Estudo'!X8,"")) -> 8 | C12: =IF(B12="","",'Dados - Fase Plástica'!M20) -> 0.77175 | D12: =IF(B12="","",'Dados - Fase Plástica'!O20) -> 251.78472 | E12: =IF(B12="","",'Dados - Fase Plástica'!P20) -> 251.78472 | F12: =AVERAGEIFS(CPs[Fcj (MPa)],CPs[Idade],'Escopo de Estudo'!$D$36,CPs[Tipo de CP],'Escopo de Estudo'!$J$36,CPs[m],B12) -> 22.039555 | G12: =AVERAGEIFS(CPs[Índice de Eficiência],CPs[Idade],'Escopo de Estudo'!$D$36,CPs[Tipo de CP],'Escopo de Estudo'!$J$36,CPs[m],B12) -> 11.42422 | H12: =IF(B12="","",'Dados - Fase Plástica'!F20) -> 200
A13: 7 | B13: =IF('Escopo de Estudo'!AG8="OK",IF('Escopo de Estudo'!AB10=TRUE,'Escopo de Estudo'!AB8,"")) -> 9 | C13: =IF(B13="","",'Dados - Fase Plástica'!M23) -> 0.8771 | D13: =IF(B13="","",'Dados - Fase Plástica'!O23) -> 226.19792 | E13: =IF(B13="","",'Dados - Fase Plástica'!P23) -> 226.19792 | F13: =AVERAGEIFS(CPs[Fcj (MPa)],CPs[Idade],'Escopo de Estudo'!$D$36,CPs[Tipo de CP],'Escopo de Estudo'!$J$36,CPs[m],B13) -> 14.9844 | G13: =AVERAGEIFS(CPs[Índice de Eficiência],CPs[Idade],'Escopo de Estudo'!$D$36,CPs[Tipo de CP],'Escopo de Estudo'!$J$36,CPs[m],B13) -> 15.09556 | H13: =IF(B13="","",'Dados - Fase Plástica'!F23) -> 100
A34: a/c x m | N34: m x Consumo | AA34: Resistência x a/c | AN34: a/c x Resistência | BA34: m x Índice de Eficiência
A36: m\x^n | B36: 6 | C36: 5 | D36: 4 | E36: 3 | F36: 2 | G36: 1 | H36: 0 | N36: m\x^n | O36: 6 | P36: 5 | Q36: 4 | R36: 3 | S36: 2 | T36: 1 | U36: 0 | AA36: m\x^n | AB36: 6 | AC36: 5 | AD36: 4 | AE36: 3 | AF36: 2 | AG36: 1 | AH36: 0 | AN36: m\x^n | AO36: 6 | AP36: 5 | AQ36: 4 | AR36: 3 | AS36: 2 | AT36: 1 | AU36: 0 | BA36: m\x^n | BB36: 6 | BC36: 5 | BD36: 4 | BE36: 3 | BF36: 2 | BG36: 1 | BH36: 0
A37: 2 | B37: =IF($C$7="","",$C$7^B36) -> 0.0015733738 | C37: =IF($C$7="","",$C$7^C36) -> 0.0046134583 | D37: =IF($C$7="","",$C$7^D36) -> 0.013527616 | E37: =IF($C$7="","",$C$7^E36) -> 0.039665776 | F37: =IF($C$7="","",$C$7^F36) -> 0.11630828 | G37: =IF($C$7="","",$C$7^G36) -> 0.34104 | H37: =IF($C$7="","",$C$7^H36) -> 1 | I37: =IF($B$4=7,MDETERM(B37:H43),IF($B$4=6,MDETERM(C37:H42),IF($B$4=5,MDETERM(D37:H41),IF($B$4=4,MDETERM(E37:H40),IF($B$4=3,MDETERM(F37:H39),"ERRO"))))) -> -1.816446e-15 | K37: Equação | L37: =IF(B4=7,I47/I37,0) -> 5525.6818 | N37: 2 | O37: =IF($B$7="","",$B$7^O36) -> 729 | P37: =IF($B$7="","",$B$7^P36) -> 243 | Q37: =IF($B$7="","",$B$7^Q36) -> 81 | R37: =IF($B$7="","",$B$7^R36) -> 27 | S37: =IF($B$7="","",$B$7^S36) -> 9 | T37: =IF($B$7="","",$B$7^T36) -> 3 | U37: =IF($B$7="","",$B$7^U36) -> 1 | V37: =IF($B$4=7,MDETERM(O37:U43),IF($B$4=6,MDETERM(P37:U42),IF($B$4=5,MDETERM(Q37:U41),IF($B$4=4,MDETERM(R37:U40),IF($B$4=3,MDETERM(S37:U39),"ERRO"))))) -> -24883200 | X37: Equação | Y37: =IF($B$4=7,V47/V37,0) -> 0.015534152 | AA37: 2 | AB37: =IF($C$7="","",$C$7^AB36) -> 0.0015733738 | AC37: =IF($C$7="","",$C$7^AC36) -> 0.0046134583 | AD37: =IF($C$7="","",$C$7^AD36) -> 0.013527616 | AE37: =IF($C$7="","",$C$7^AE36) -> 0.039665776 | AF37: =IF($C$7="","",$C$7^AF36) -> 0.11630828 | AG37: =IF($C$7="","",$C$7^AG36) -> 0.34104 | AH37: =IF($C$7="","",$C$7^AH36) -> 1 | AI37: =IF($B$4=7,MDETERM(AB37:AH43),IF($B$4=6,MDETERM(AC37:AH42),IF($B$4=5,MDETERM(AD37:AH41),IF($B$4=4,MDETERM(AE37:AH40),IF($B$4=3,MDETERM(AF37:AH39),"ERRO"))))) -> -1.816446e-15 | AK37: Equação | AL37: =IF($B$4=7,AI47/AI37,0) -> 267549.14 | AN37: 2 | AO37: =IF($F$7="","",$F$7^AO36) -> 8.4024104e+10 | AP37: =IF($F$7="","",$F$7^AP36) -> 1.2696087e+09 | AQ37: =IF($F$7="","",$F$7^AQ36) -> 19183857 | AR37: =IF($F$7="","",$F$7^AR36) -> 289869.11 | AS37: =IF($F$7="","",$F$7^AS36) -> 4379.938 | AT37: =IF($F$7="","",$F$7^AT36) -> 66.1811 | AU37: =IF($F$7="","",$F$7^AU36) -> 1 | AV37: =IF($B$4=7,MDETERM(AO37:AU43),IF($B$4=6,MDETERM(AP37:AU42),IF($B$4=5,MDETERM(AQ37:AU41),IF($B$4=4,MDETERM(AR37:AU40),IF($B$4=3,MDETERM(AS37:AU39),"ERRO"))))) -> 9.4605829e+25 | AX37: Equação | AY37: =IF($B$4=7,AV47/AV37,0) -> 2.046823e-09 | BA37: 2 | BB37: =IF($B$7="","",$B$7^BB36) -> 729 | BC37: =IF($B$7="","",$B$7^BC36) -> 243 | BD37: =IF($B$7="","",$B$7^BD36) -> 81 | BE37: =IF($B$7="","",$B$7^BE36) -> 27 | BF37: =IF($B$7="","",$B$7^BF36) -> 9 | BG37: =IF($B$7="","",$B$7^BG36) -> 3 | BH37: =IF($B$7="","",$B$7^BH36) -> 1 | BI37: =IF($B$4=7,MDETERM(BB37:BH43),IF($B$4=6,MDETERM(BC37:BH42),IF($B$4=5,MDETERM(BD37:BH41),IF($B$4=4,MDETERM(BE37:BH40),IF($B$4=3,MDETERM(BF37:BH39),"ERRO"))))) -> -24883200 | BK37: Equação | BL37: =IF($B$4=7,BI47/BI37,0) -> -0.029027184
A38: 3 | B38: =IF($C$8="","",$C$8^B36) -> 0.0062119049 | C38: =IF($C$8="","",$C$8^C36) -> 0.014488408 | D38: =IF($C$8="","",$C$8^D36) -> 0.033792205 | E38: =IF($C$8="","",$C$8^E36) -> 0.078815639 | F38: =IF($C$8="","",$C$8^F36) -> 0.18382656 | G38: =IF($C$8="","",$C$8^G36) -> 0.42875 | H38: =IF($C$8="","",$C$8^H36) -> 1 | L38: =IF(B4>=6,I56/I37,0) -> -20458.828 | N38: 3 | O38: =IF($B$8="","",$B$8^O36) -> 4096 | P38: =IF($B$8="","",$B$8^P36) -> 1024 | Q38: =IF($B$8="","",$B$8^Q36) -> 256 | R38: =IF($B$8="","",$B$8^R36) -> 64 | S38: =IF($B$8="","",$B$8^S36) -> 16 | T38: =IF($B$8="","",$B$8^T36) -> 4 | U38: =IF($B$8="","",$B$8^U36) -> 1 | Y38: =IF(B4>=6,V56/V37,0) -> -0.59755962 | AA38: 3 | AB38: =IF($C$8="","",$C$8^AB36) -> 0.0062119049 | AC38: =IF($C$8="","",$C$8^AC36) -> 0.014488408 | AD38: =IF($C$8="","",$C$8^AD36) -> 0.033792205 | AE38: =IF($C$8="","",$C$8^AE36) -> 0.078815639 | AF38: =IF($C$8="","",$C$8^AF36) -> 0.18382656 | AG38: =IF($C$8="","",$C$8^AG36) -> 0.42875 | AH38: =IF($C$8="","",$C$8^AH36) -> 1 | AL38: =IF($B$4>=6,AI56/AI37,0) -> -989364.94 | AN38: 3 | AO38: =IF($F$8="","",$F$8^AO36) -> 1.5527753e+10 | AP38: =IF($F$8="","",$F$8^AP36) -> 3.1087838e+08 | AQ38: =IF($F$8="","",$F$8^AQ36) -> 6224040.5 | AR38: =IF($F$8="","",$F$8^AR36) -> 124610.41 | AS38: =IF($F$8="","",$F$8^AS36) -> 2494.8027 | AT38: =IF($F$8="","",$F$8^AT36) -> 49.948 | AU38: =IF($F$8="","",$F$8^AU36) -> 1 | AY38: =IF($B$4>=6,AV56/AV37,0) -> -4.0507187e-07 | BA38: 3 | BB38: =IF($B$8="","",$B$8^BB36) -> 4096 | BC38: =IF($B$8="","",$B$8^BC36) -> 1024 | BD38: =IF($B$8="","",$B$8^BD36) -> 256 | BE38: =IF($B$8="","",$B$8^BE36) -> 64 | BF38: =IF($B$8="","",$B$8^BF36) -> 16 | BG38: =IF($B$8="","",$B$8^BG36) -> 4 | BH38: =IF($B$8="","",$B$8^BH36) -> 1 | BL38: =IF($B$4>=6,BI56/BI37,0) -> 1.0828409
A39: 4 | B39: =IF($C$9="","",$C$9^B36) -> 0.016720708 | C39: =IF($C$9="","",$C$9^C36) -> 0.033065789 | D39: =IF($C$9="","",$C$9^D36) -> 0.065388761 | E39: =IF($C$9="","",$C$9^E36) -> 0.12930858 | F39: =IF($C$9="","",$C$9^F36) -> 0.25571226 | G39: =IF($C$9="","",$C$9^G36) -> 0.50568 | H39: =IF($C$9="","",$C$9^H36) -> 1 | L39: =IF(B4>=5,I65/I37,0) -> 30959.32 | N39: 4 | O39: =IF($B$9="","",$B$9^O36) -> 15625 | P39: =IF($B$9="","",$B$9^P36) -> 3125 | Q39: =IF($B$9="","",$B$9^Q36) -> 625 | R39: =IF($B$9="","",$B$9^R36) -> 125 | S39: =IF($B$9="","",$B$9^S36) -> 25 | T39: =IF($B$9="","",$B$9^T36) -> 5 | U39: =IF($B$9="","",$B$9^U36) -> 1 | Y39: =IF(B4>=5,V65/V37,0) -> 9.5145537 | AA39: 4 | AB39: =IF($C$9="","",$C$9^AB36) -> 0.016720708 | AC39: =IF($C$9="","",$C$9^AC36) -> 0.033065789 | AD39: =IF($C$9="","",$C$9^AD36) -> 0.065388761 | AE39: =IF($C$9="","",$C$9^AE36) -> 0.12930858 | AF39: =IF($C$9="","",$C$9^AF36) -> 0.25571226 | AG39: =IF($C$9="","",$C$9^AG36) -> 0.50568 | AH39: =IF($C$9="","",$C$9^AH36) -> 1 | AL39: =IF($B$4>=5,AI65/AI37,0) -> 1496179.2 | AN39: 4 | AO39: =IF($F$9="","",$F$9^AO36) -> 8.2520847e+09 | AP39: =IF($F$9="","",$F$9^AP36) -> 1.8357057e+08 | AQ39: =IF($F$9="","",$F$9^AQ36) -> 4083593 | AR39: =IF($F$9="","",$F$9^AR36) -> 90840.986 | AS39: =IF($F$9="","",$F$9^AS36) -> 2020.7902 | AT39: =IF($F$9="","",$F$9^AT36) -> 44.9532 | AU39: =IF($F$9="","",$F$9^AU36) -> 1 | AY39: =IF($B$4>=5,AV65/AV37,0) -> 3.0657969e-05 | BA39: 4 | BB39: =IF($B$9="","",$B$9^BB36) -> 15625 | BC39: =IF($B$9="","",$B$9^BC36) -> 3125 | BD39: =IF($B$9="","",$B$9^BD36) -> 625 | BE39: =IF($B$9="","",$B$9^BE36) -> 125 | BF39: =IF($B$9="","",$B$9^BF36) -> 25 | BG39: =IF($B$9="","",$B$9^BG36) -> 5 | BH39: =IF($B$9="","",$B$9^BH36) -> 1 | BL39: =IF($B$4>=5,BI65/BI37,0) -> -16.391325
A40: 5 | B40: =IF($C$10="","",$C$10^B36) -> 0.046772762 | C40: =IF($C$10="","",$C$10^C36) -> 0.077922135 | D40: =IF($C$10="","",$C$10^D36) -> 0.12981614 | E40: =IF($C$10="","",$C$10^E36) -> 0.21627011 | F40: =IF($C$10="","",$C$10^F36) -> 0.36030006 | G40: =IF($C$10="","",$C$10^G36) -> 0.60025 | H40: =IF($C$10="","",$C$10^H36) -> 1 | L40: =IF(B4>=4,I74/I37,0) -> -24481.141 | N40: 5 | O40: =IF($B$10="","",$B$10^O36) -> 46656 | P40: =IF($B$10="","",$B$10^P36) -> 7776 | Q40: =IF($B$10="","",$B$10^Q36) -> 1296 | R40: =IF($B$10="","",$B$10^R36) -> 216 | S40: =IF($B$10="","",$B$10^S36) -> 36 | T40: =IF($B$10="","",$B$10^T36) -> 6 | U40: =IF($B$10="","",$B$10^U36) -> 1 | Y40: =IF(B4>=4,V74/V37,0) -> -81.118132 | AA40: 5 | AB40: =IF($C$10="","",$C$10^AB36) -> 0.046772762 | AC40: =IF($C$10="","",$C$10^AC36) -> 0.077922135 | AD40: =IF($C$10="","",$C$10^AD36) -> 0.12981614 | AE40: =IF($C$10="","",$C$10^AE36) -> 0.21627011 | AF40: =IF($C$10="","",$C$10^AF36) -> 0.36030006 | AG40: =IF($C$10="","",$C$10^AG36) -> 0.60025 | AH40: =IF($C$10="","",$C$10^AH36) -> 1 | AL40: =IF($B$4>=4,AI74/AI37,0) -> -1183011.9 | AN40: 5 | AO40: =IF($F$10="","",$F$10^AO36) -> 8.6294903e+08 | AP40: =IF($F$10="","",$F$10^AP36) -> 27967541 | AQ40: =IF($F$10="","",$F$10^AQ36) -> 906407.37 | AR40: =IF($F$10="","",$F$10^AR36) -> 29375.994 | AS40: =IF($F$10="","",$F$10^AS36) -> 952.05429 | AT40: =IF($F$10="","",$F$10^AT36) -> 30.855377 | AU40: =IF($F$10="","",$F$10^AU36) -> 1 | AY40: =IF($B$4>=4,AV74/AV37,0) -> -0.0011136303 | BA40: 5 | BB40: =IF($B$10="","",$B$10^BB36) -> 46656 | BC40: =IF($B$10="","",$B$10^BC36) -> 7776 | BD40: =IF($B$10="","",$B$10^BD36) -> 1296 | BE40: =IF($B$10="","",$B$10^BE36) -> 216 | BF40: =IF($B$10="","",$B$10^BF36) -> 36 | BG40: =IF($B$10="","",$B$10^BG36) -> 6 | BH40: =IF($B$10="","",$B$10^BH36) -> 1 | BL40: =IF($B$4>=4,BI74/BI37,0) -> 128.57449
A41: 6 | B41: =IF($C$11="","",$C$11^B36) -> 0.10244458 | C41: =IF($C$11="","",$C$11^C36) -> 0.14976402 | D41: =IF($C$11="","",$C$11^D36) -> 0.21894044 | E41: =IF($C$11="","",$C$11^E36) -> 0.32006965 | F41: =IF($C$11="","",$C$11^F36) -> 0.46791072 | G41: =IF($C$11="","",$C$11^G36) -> 0.68404 | H41: =IF($C$11="","",$C$11^H36) -> 1 | L41: =I83/I37 -> 10655.292 | N41: 6 | O41: =IF($B$11="","",$B$11^O36) -> 117649 | P41: =IF($B$11="","",$B$11^P36) -> 16807 | Q41: =IF($B$11="","",$B$11^Q36) -> 2401 | R41: =IF($B$11="","",$B$11^R36) -> 343 | S41: =IF($B$11="","",$B$11^S36) -> 49 | T41: =IF($B$11="","",$B$11^T36) -> 7 | U41: =IF($B$11="","",$B$11^U36) -> 1 | Y41: =V83/V37 -> 400.76811 | AA41: 6 | AB41: =IF($C$11="","",$C$11^AB36) -> 0.10244458 | AC41: =IF($C$11="","",$C$11^AC36) -> 0.14976402 | AD41: =IF($C$11="","",$C$11^AD36) -> 0.21894044 | AE41: =IF($C$11="","",$C$11^AE36) -> 0.32006965 | AF41: =IF($C$11="","",$C$11^AF36) -> 0.46791072 | AG41: =IF($C$11="","",$C$11^AG36) -> 0.68404 | AH41: =IF($C$11="","",$C$11^AH36) -> 1 | AL41: =AI83/AI37 -> 515328.41 | AN41: 6 | AO41: =IF($F$11="","",$F$11^AO36) -> 3.2513554e+08 | AP41: =IF($F$11="","",$F$11^AP36) -> 12399011 | AQ41: =IF($F$11="","",$F$11^AQ36) -> 472835.01 | AR41: =IF($F$11="","",$F$11^AR36) -> 18031.515 | AS41: =IF($F$11="","",$F$11^AS36) -> 687.63 | AT41: =IF($F$11="","",$F$11^AT36) -> 26.2227 | AU41: =IF($F$11="","",$F$11^AU36) -> 1 | AY41: =AV83/AV37 -> 0.019971618 | BA41: 6 | BB41: =IF($B$11="","",$B$11^BB36) -> 117649 | BC41: =IF($B$11="","",$B$11^BC36) -> 16807 | BD41: =IF($B$11="","",$B$11^BD36) -> 2401 | BE41: =IF($B$11="","",$B$11^BE36) -> 343 | BF41: =IF($B$11="","",$B$11^BF36) -> 49 | BG41: =IF($B$11="","",$B$11^BG36) -> 7 | BH41: =IF($B$11="","",$B$11^BH36) -> 1 | BL41: =BI83/BI37 -> -549.73562
A42: 7 | B42: =IF($C$12="","",$C$12^B36) -> 0.2112807 | C42: =IF($C$12="","",$C$12^C36) -> 0.27376832 | D42: =IF($C$12="","",$C$12^D36) -> 0.35473705 | E42: =IF($C$12="","",$C$12^E36) -> 0.4596528 | F42: =IF($C$12="","",$C$12^F36) -> 0.59559806 | G42: =IF($C$12="","",$C$12^G36) -> 0.77175 | H42: =IF($C$12="","",$C$12^H36) -> 1 | L42: =I92/I37 -> -2405.3437 | N42: 7 | O42: =IF($B$12="","",$B$12^O36) -> 262144 | P42: =IF($B$12="","",$B$12^P36) -> 32768 | Q42: =IF($B$12="","",$B$12^Q36) -> 4096 | R42: =IF($B$12="","",$B$12^R36) -> 512 | S42: =IF($B$12="","",$B$12^S36) -> 64 | T42: =IF($B$12="","",$B$12^T36) -> 8 | U42: =IF($B$12="","",$B$12^U36) -> 1 | Y42: =V92/V37 -> -1168.2211 | AA42: 7 | AB42: =IF($C$12="","",$C$12^AB36) -> 0.2112807 | AC42: =IF($C$12="","",$C$12^AC36) -> 0.27376832 | AD42: =IF($C$12="","",$C$12^AD36) -> 0.35473705 | AE42: =IF($C$12="","",$C$12^AE36) -> 0.4596528 | AF42: =IF($C$12="","",$C$12^AF36) -> 0.59559806 | AG42: =IF($C$12="","",$C$12^AG36) -> 0.77175 | AH42: =IF($C$12="","",$C$12^AH36) -> 1 | AL42: =AI92/AI37 -> -117274.32 | AN42: 7 | AO42: =IF($F$12="","",$F$12^AO36) -> 1.1460853e+08 | AP42: =IF($F$12="","",$F$12^AP36) -> 5200128.9 | AQ42: =IF($F$12="","",$F$12^AQ36) -> 235945.28 | AR42: =IF($F$12="","",$F$12^AR36) -> 10705.537 | AS42: =IF($F$12="","",$F$12^AS36) -> 485.74198 | AT42: =IF($F$12="","",$F$12^AT36) -> 22.039555 | AU42: =IF($F$12="","",$F$12^AU36) -> 1 | AY42: =AV92/AV37 -> -0.17659306 | BA42: 7 | BB42: =IF($B$12="","",$B$12^BB36) -> 262144 | BC42: =IF($B$12="","",$B$12^BC36) -> 32768 | BD42: =IF($B$12="","",$B$12^BD36) -> 4096 | BE42: =IF($B$12="","",$B$12^BE36) -> 512 | BF42: =IF($B$12="","",$B$12^BF36) -> 64 | BG42: =IF($B$12="","",$B$12^BG36) -> 8 | BH42: =IF($B$12="","",$B$12^BH36) -> 1 | BL42: =BI92/BI37 -> 1211.9207
A43: 8 | B43: =IF($C$13="","",$C$13^B36) -> 0.45529687 | C43: =IF($C$13="","",$C$13^C36) -> 0.51909346 | D43: =IF($C$13="","",$C$13^D36) -> 0.59182928 | E43: =IF($C$13="","",$C$13^E36) -> 0.6747569 | F43: =IF($C$13="","",$C$13^F36) -> 0.76930441 | G43: =IF($C$13="","",$C$13^G36) -> 0.8771 | H43: =IF($C$13="","",$C$13^H36) -> 1 | L43: =I101/I37 -> 221.96942 | N43: 8 | O43: =IF($B$13="","",$B$13^O36) -> 531441 | P43: =IF($B$13="","",$B$13^P36) -> 59049 | Q43: =IF($B$13="","",$B$13^Q36) -> 6561 | R43: =IF($B$13="","",$B$13^R36) -> 729 | S43: =IF($B$13="","",$B$13^S36) -> 81 | T43: =IF($B$13="","",$B$13^T36) -> 9 | U43: =IF($B$13="","",$B$13^U36) -> 1 | Y43: =V101/V37 -> 2017.9151 | AA43: 8 | AB43: =IF($C$13="","",$C$13^AB36) -> 0.45529687 | AC43: =IF($C$13="","",$C$13^AC36) -> 0.51909346 | AD43: =IF($C$13="","",$C$13^AD36) -> 0.59182928 | AE43: =IF($C$13="","",$C$13^AE36) -> 0.6747569 | AF43: =IF($C$13="","",$C$13^AF36) -> 0.76930441 | AG43: =IF($C$13="","",$C$13^AG36) -> 0.8771 | AH43: =IF($C$13="","",$C$13^AH36) -> 1 | AL43: =AI101/AI37 -> 10953.239 | AN43: 8 | AO43: =IF($F$13="","",$F$13^AO36) -> 11319732 | AP43: =IF($F$13="","",$F$13^AP36) -> 755434.45 | AQ43: =IF($F$13="","",$F$13^AQ36) -> 50414.728 | AR43: =IF($F$13="","",$F$13^AR36) -> 3364.4809 | AS43: =IF($F$13="","",$F$13^AS36) -> 224.53224 | AT43: =IF($F$13="","",$F$13^AT36) -> 14.9844 | AU43: =IF($F$13="","",$F$13^AU36) -> 1 | AY43: =AV101/AV37 -> 1.5229794 | BA43: 8 | BB43: =IF($B$13="","",$B$13^BB36) -> 531441 | BC43: =IF($B$13="","",$B$13^BC36) -> 59049 | BD43: =IF($B$13="","",$B$13^BD36) -> 6561 | BE43: =IF($B$13="","",$B$13^BE36) -> 729 | BF43: =IF($B$13="","",$B$13^BF36) -> 81 | BG43: =IF($B$13="","",$B$13^BG36) -> 9 | BH43: =IF($B$13="","",$B$13^BH36) -> 1 | BL43: =BI101/BI37 -> -1065.361
K44: =AX45 -> 0.81076465 | L44: a/c Desejado | X44: =K45 -> 8.337328 | Y44: m Desejado | AK44: =AX45 -> 0.81076465 | AL44: =IF(AK44="","",$AL$37*(AK44^6)+$AL$38*(AK44^5)+$AL$39*(AK44^4)+$AL$40*(AK44^3)+$AL$41*(AK44^2)+$AL$42*(AK44^1)+$AL$43) -> 16.507135 | AX44: ='Avaliação de Resultado'!B7 -> 20 | AY44: Resistência Desejada | BK44: =K45 -> 8.337328 | BL44: m Desejado
K45: =IF(K44="","",$L$37*(K44^6)+$L$38*(K44^5)+$L$39*(K44^4)+$L$40*(K44^3)+$L$41*(K44^2)+$L$42*(K44^1)+$L$43) -> 8.337328 | L45: m | X45: =IF(X44="","",$Y$37*(X44^6)+$Y$38*(X44^5)+$Y$39*(X44^4)+$Y$40*(X44^3)+$Y$41*(X44^2)+$Y$42*(X44^1)+$Y$43) -> 242.39077 | Y45: Consumo | AL45: =(AX44-AL44)/AX44 -> 0.17464326 | AX45: =IF(AX44="","",$AY$37*(AX44^6)+$AY$38*(AX44^5)+$AY$39*(AX44^4)+$AY$40*(AX44^3)+$AY$41*(AX44^2)+$AY$42*(AX44^1)+$AY$43) -> 0.81076465 | AY45: a/c | BK45: =IF(BK44="","",$BL$37*(BK44^6)+$BL$38*(BK44^5)+$BL$39*(BK44^4)+$BL$40*(BK44^3)+$BL$41*(BK44^2)+$BL$42*(BK44^1)+$BL$43) -> 12.57365 | BL45: IRF
A46: m\x^n | B46: 6 | C46: 5 | D46: 4 | E46: 3 | F46: 2 | G46: 1 | H46: 0 | K46: Validação | N46: m\x^n | O46: 6 | P46: 5 | Q46: 4 | R46: 3 | S46: 2 | T46: 1 | U46: 0 | X46: Validação | AA46: m\x^n | AB46: 6 | AC46: 5 | AD46: 4 | AE46: 3 | AF46: 2 | AG46: 1 | AH46: 0 | AK46: Validação | AN46: m\x^n | AO46: 6 | AP46: 5 | AQ46: 4 | AR46: 3 | AS46: 2 | AT46: 1 | AU46: 0 | AX46: Validação | BA46: m\x^n | BB46: 6 | BC46: 5 | BD46: 4 | BE46: 3 | BF46: 2 | BG46: 1 | BH46: 0 | BK46: Validação
A47: 2 | B47: =B7 -> 3 | C47: =C37 -> 0.0046134583 | D47: =D37 -> 0.013527616 | E47: =E37 -> 0.039665776 | F47: =F37 -> 0.11630828 | G47: =G37 -> 0.34104 | H47: =H37 -> 1 | I47: =IF($B$4=7,MDETERM(B47:H53),IF($B$4=6,MDETERM(C47:H52),IF($B$4=5,MDETERM(D47:H51),IF($B$4=4,MDETERM(E47:H50),IF($B$4=3,MDETERM(F47:H49),"ERRO"))))) -> -1.0037103e-11 | K47: a/c | L47: m | N47: 2 | O47: =D7 -> 566.77141 | P47: =P37 -> 243 | Q47: =Q37 -> 81 | R47: =R37 -> 27 | S47: =S37 -> 9 | T47: =T37 -> 3 | U47: =U37 -> 1 | V47: =IF($B$4=7,MDETERM(O47:U53),IF($B$4=6,MDETERM(P47:U52),IF($B$4=5,MDETERM(Q47:U51),IF($B$4=4,MDETERM(R47:U50),IF($B$4=3,MDETERM(S47:U49),"ERRO"))))) -> -386539.42 | X47: m | Y47: Consumo | AA47: 2 | AB47: =F7 -> 66.1811 | AC47: =AC37 -> 0.0046134583 | AD47: =AD37 -> 0.013527616 | AE47: =AE37 -> 0.039665776 | AF47: =AF37 -> 0.11630828 | AG47: =AG37 -> 0.34104 | AH47: =AH37 -> 1 | AI47: =IF($B$4=7,MDETERM(AB47:AH53),IF($B$4=6,MDETERM(AC47:AH52),IF($B$4=5,MDETERM(AD47:AH51),IF($B$4=4,MDETERM(AE47:AH50),IF($B$4=3,MDETERM(AF47:AH49),"ERRO"))))) -> -4.8598858e-10 | AK47: a/c | AL47: Resistência | AN47: 2 | AO47: =C7 -> 0.34104 | AP47: =AP37 -> 1.2696087e+09 | AQ47: =AQ37 -> 19183857 | AR47: =AR37 -> 289869.11 | AS47: =AS37 -> 4379.938 | AT47: =AT37 -> 66.1811 | AU47: =AU37 -> 1 | AV47: =IF($B$4=7,MDETERM(AO47:AU53),IF($B$4=6,MDETERM(AP47:AU52),IF($B$4=5,MDETERM(AQ47:AU51),IF($B$4=4,MDETERM(AR47:AU50),IF($B$4=3,MDETERM(AS47:AU49),"ERRO"))))) -> 1.9364139e+17 | AX47: Resistência | AY47: a/c | BA47: 2 | BB47: =G7 -> 8.5639466 | BC47: =BC37 -> 243 | BD47: =BD37 -> 81 | BE47: =BE37 -> 27 | BF47: =BF37 -> 9 | BG47: =BG37 -> 3 | BH47: =BH37 -> 1 | BI47: =IF($B$4=7,MDETERM(BB47:BH53),IF($B$4=6,MDETERM(BC47:BH52),IF($B$4=5,MDETERM(BD47:BH51),IF($B$4=4,MDETERM(BE47:BH50),IF($B$4=3,MDETERM(BF47:BH49),"ERRO"))))) -> 722289.23 | BK47: m | BL47: IEF
A48: 3 | B48: =B8 -> 4 | C48: =C38 -> 0.014488408 | D48: =D38 -> 0.033792205 | E48: =E38 -> 0.078815639 | F48: =F38 -> 0.18382656 | G48: =G38 -> 0.42875 | H48: =H38 -> 1 | K48: =C7 -> 0.34104 | L48: =IF(K48="","",$L$37*(K48^6)+$L$38*(K48^5)+$L$39*(K48^4)+$L$40*(K48^3)+$L$41*(K48^2)+$L$42*(K48^1)+$L$43) -> 3 | N48: 3 | O48: =D8 -> 453.2125 | P48: =P38 -> 1024 | Q48: =Q38 -> 256 | R48: =R38 -> 64 | S48: =S38 -> 16 | T48: =T38 -> 4 | U48: =U38 -> 1 | X48: =B7 -> 3 | Y48: =IF(X48="","",$Y$37*(X48^6)+$Y$38*(X48^5)+$Y$39*(X48^4)+$Y$40*(X48^3)+$Y$41*(X48^2)+$Y$42*(X48^1)+$Y$43) -> 566.77141 | AA48: 3 | AB48: =F8 -> 49.948 | AC48: =AC38 -> 0.014488408 | AD48: =AD38 -> 0.033792205 | AE48: =AE38 -> 0.078815639 | AF48: =AF38 -> 0.18382656 | AG48: =AG38 -> 0.42875 | AH48: =AH38 -> 1 | AK48: =C7 -> 0.34104 | AL48: =IF(AK48="","",$AL$37*(AK48^6)+$AL$38*(AK48^5)+$AL$39*(AK48^4)+$AL$40*(AK48^3)+$AL$41*(AK48^2)+$AL$42*(AK48^1)+$AL$43) -> 66.1811 | AN48: 3 | AO48: =C8 -> 0.42875 | AP48: =AP38 -> 3.1087838e+08 | AQ48: =AQ38 -> 6224040.5 | AR48: =AR38 -> 124610.41 | AS48: =AS38 -> 2494.8027 | AT48: =AT38 -> 49.948 | AU48: =AU38 -> 1 | AX48: =F7 -> 66.1811 | AY48: =IF(AX48="","",$AY$37*(AX48^6)+$AY$38*(AX48^5)+$AY$39*(AX48^4)+$AY$40*(AX48^3)+$AY$41*(AX48^2)+$AY$42*(AX48^1)+$AY$43) -> 0.34104 | BA48: 3 | BB48: =G8 -> 9.0736866 | BC48: =BC38 -> 1024 | BD48: =BD38 -> 256 | BE48: =BE38 -> 64 | BF48: =BF38 -> 16 | BG48: =BG38 -> 4 | BH48: =BH38 -> 1 | BK48: =B7 -> 3 | BL48: =IF(BK48="","",$BL$37*(BK48^6)+$BL$38*(BK48^5)+$BL$39*(BK48^4)+$BL$40*(BK48^3)+$BL$41*(BK48^2)+$BL$42*(BK48^1)+$BL$43) -> 8.5639466
A49: 4 | B49: =B9 -> 5 | C49: =C39 -> 0.033065789 | D49: =D39 -> 0.065388761 | E49: =E39 -> 0.12930858 | F49: =F39 -> 0.25571226 | G49: =G39 -> 0.50568 | H49: =H39 -> 1 | K49: =C8 -> 0.42875 | L49: =IF(K49="","",$L$37*(K49^6)+$L$38*(K49^5)+$L$39*(K49^4)+$L$40*(K49^3)+$L$41*(K49^2)+$L$42*(K49^1)+$L$43) -> 4 | N49: 4 | O49: =D9 -> 378.18911 | P49: =P39 -> 3125 | Q49: =Q39 -> 625 | R49: =R39 -> 125 | S49: =S39 -> 25 | T49: =T39 -> 5 | U49: =U39 -> 1 | X49: =B8 -> 4 | Y49: =IF(X49="","",$Y$37*(X49^6)+$Y$38*(X49^5)+$Y$39*(X49^4)+$Y$40*(X49^3)+$Y$41*(X49^2)+$Y$42*(X49^1)+$Y$43) -> 453.2125 | AA49: 4 | AB49: =F9 -> 44.9532 | AC49: =AC39 -> 0.033065789 | AD49: =AD39 -> 0.065388761 | AE49: =AE39 -> 0.12930858 | AF49: =AF39 -> 0.25571226 | AG49: =AG39 -> 0.50568 | AH49: =AH39 -> 1 | AK49: =C8 -> 0.42875 | AL49: =IF(AK49="","",$AL$37*(AK49^6)+$AL$38*(AK49^5)+$AL$39*(AK49^4)+$AL$40*(AK49^3)+$AL$41*(AK49^2)+$AL$42*(AK49^1)+$AL$43) -> 49.948 | AN49: 4 | AO49: =C9 -> 0.50568 | AP49: =AP39 -> 1.8357057e+08 | AQ49: =AQ39 -> 4083593 | AR49: =AR39 -> 90840.986 | AS49: =AS39 -> 2020.7902 | AT49: =AT39 -> 44.9532 | AU49: =AU39 -> 1 | AX49: =F8 -> 49.948 | AY49: =IF(AX49="","",$AY$37*(AX49^6)+$AY$38*(AX49^5)+$AY$39*(AX49^4)+$AY$40*(AX49^3)+$AY$41*(AX49^2)+$AY$42*(AX49^1)+$AY$43) -> 0.42875 | BA49: 4 | BB49: =G9 -> 8.412952 | BC49: =BC39 -> 3125 | BD49: =BD39 -> 625 | BE49: =BE39 -> 125 | BF49: =BF39 -> 25 | BG49: =BG39 -> 5 | BH49: =BH39 -> 1 | BK49: =B8 -> 4 | BL49: =IF(BK49="","",$BL$37*(BK49^6)+$BL$38*(BK49^5)+$BL$39*(BK49^4)+$BL$40*(BK49^3)+$BL$41*(BK49^2)+$BL$42*(BK49^1)+$BL$43) -> 9.0736866
A50: 5 | B50: =B10 -> 6 | C50: =C40 -> 0.077922135 | D50: =D40 -> 0.12981614 | E50: =E40 -> 0.21627011 | F50: =F40 -> 0.36030006 | G50: =G40 -> 0.60025 | H50: =H40 -> 1 | K50: =C9 -> 0.50568 | L50: =IF(K50="","",$L$37*(K50^6)+$L$38*(K50^5)+$L$39*(K50^4)+$L$40*(K50^3)+$L$41*(K50^2)+$L$42*(K50^1)+$L$43) -> 5 | N50: 5 | O50: =D10 -> 323.72321 | P50: =P40 -> 7776 | Q50: =Q40 -> 1296 | R50: =R40 -> 216 | S50: =S40 -> 36 | T50: =T40 -> 6 | U50: =U40 -> 1 | X50: =B9 -> 5 | Y50: =IF(X50="","",$Y$37*(X50^6)+$Y$38*(X50^5)+$Y$39*(X50^4)+$Y$40*(X50^3)+$Y$41*(X50^2)+$Y$42*(X50^1)+$Y$43) -> 378.18911 | AA50: 5 | AB50: =F10 -> 30.855377 | AC50: =AC40 -> 0.077922135 | AD50: =AD40 -> 0.12981614 | AE50: =AE40 -> 0.21627011 | AF50: =AF40 -> 0.36030006 | AG50: =AG40 -> 0.60025 | AH50: =AH40 -> 1 | AK50: =C9 -> 0.50568 | AL50: =IF(AK50="","",$AL$37*(AK50^6)+$AL$38*(AK50^5)+$AL$39*(AK50^4)+$AL$40*(AK50^3)+$AL$41*(AK50^2)+$AL$42*(AK50^1)+$AL$43) -> 44.9532 | AN50: 5 | AO50: =C10 -> 0.60025 | AP50: =AP40 -> 27967541 | AQ50: =AQ40 -> 906407.37 | AR50: =AR40 -> 29375.994 | AS50: =AS40 -> 952.05429 | AT50: =AT40 -> 30.855377 | AU50: =AU40 -> 1 | AX50: =F9 -> 44.9532 | AY50: =IF(AX50="","",$AY$37*(AX50^6)+$AY$38*(AX50^5)+$AY$39*(AX50^4)+$AY$40*(AX50^3)+$AY$41*(AX50^2)+$AY$42*(AX50^1)+$AY$43) -> 0.50568 | BA50: 5 | BB50: =G10 -> 10.49163 | BC50: =BC40 -> 7776 | BD50: =BD40 -> 1296 | BE50: =BE40 -> 216 | BF50: =BF40 -> 36 | BG50: =BG40 -> 6 | BH50: =BH40 -> 1 | BK50: =B9 -> 5 | BL50: =IF(BK50="","",$BL$37*(BK50^6)+$BL$38*(BK50^5)+$BL$39*(BK50^4)+$BL$40*(BK50^3)+$BL$41*(BK50^2)+$BL$42*(BK50^1)+$BL$43) -> 8.412952
A51: 6 | B51: =B11 -> 7 | C51: =C41 -> 0.14976402 | D51: =D41 -> 0.21894044 | E51: =E41 -> 0.32006965 | F51: =F41 -> 0.46791072 | G51: =G41 -> 0.68404 | H51: =H41 -> 1 | K51: =C10 -> 0.60025 | L51: =IF(K51="","",$L$37*(K51^6)+$L$38*(K51^5)+$L$39*(K51^4)+$L$40*(K51^3)+$L$41*(K51^2)+$L$42*(K51^1)+$L$43) -> 6 | N51: 6 | O51: =D11 -> 283.32174 | P51: =P41 -> 16807 | Q51: =Q41 -> 2401 | R51: =R41 -> 343 | S51: =S41 -> 49 | T51: =T41 -> 7 | U51: =U41 -> 1 | X51: =B10 -> 6 | Y51: =IF(X51="","",$Y$37*(X51^6)+$Y$38*(X51^5)+$Y$39*(X51^4)+$Y$40*(X51^3)+$Y$41*(X51^2)+$Y$42*(X51^1)+$Y$43) -> 323.72321 | AA51: 6 | AB51: =F11 -> 26.2227 | AC51: =AC41 -> 0.14976402 | AD51: =AD41 -> 0.21894044 | AE51: =AE41 -> 0.32006965 | AF51: =AF41 -> 0.46791072 | AG51: =AG41 -> 0.68404 | AH51: =AH41 -> 1 | AK51: =C10 -> 0.60025 | AL51: =IF(AK51="","",$AL$37*(AK51^6)+$AL$38*(AK51^5)+$AL$39*(AK51^4)+$AL$40*(AK51^3)+$AL$41*(AK51^2)+$AL$42*(AK51^1)+$AL$43) -> 30.855377 | AN51: 6 | AO51: =C11 -> 0.68404 | AP51: =AP41 -> 12399011 | AQ51: =AQ41 -> 472835.01 | AR51: =AR41 -> 18031.515 | AS51: =AS41 -> 687.63 | AT51: =AT41 -> 26.2227 | AU51: =AU41 -> 1 | AX51: =F10 -> 30.855377 | AY51: =IF(AX51="","",$AY$37*(AX51^6)+$AY$38*(AX51^5)+$AY$39*(AX51^4)+$AY$40*(AX51^3)+$AY$41*(AX51^2)+$AY$42*(AX51^1)+$AY$43) -> 0.60025 | BA51: 6 | BB51: =G11 -> 10.804446 | BC51: =BC41 -> 16807 | BD51: =BD41 -> 2401 | BE51: =BE41 -> 343 | BF51: =BF41 -> 49 | BG51: =BG41 -> 7 | BH51: =BH41 -> 1 | BK51: =B10 -> 6 | BL51: =IF(BK51="","",$BL$37*(BK51^6)+$BL$38*(BK51^5)+$BL$39*(BK51^4)+$BL$40*(BK51^3)+$BL$41*(BK51^2)+$BL$42*(BK51^1)+$BL$43) -> 10.49163
A52: 7 | B52: =B12 -> 8 | C52: =C42 -> 0.27376832 | D52: =D42 -> 0.35473705 | E52: =E42 -> 0.4596528 | F52: =F42 -> 0.59559806 | G52: =G42 -> 0.77175 | H52: =H42 -> 1 | K52: =C11 -> 0.68404 | L52: =IF(K52="","",$L$37*(K52^6)+$L$38*(K52^5)+$L$39*(K52^4)+$L$40*(K52^3)+$L$41*(K52^2)+$L$42*(K52^1)+$L$43) -> 7 | N52: 7 | O52: =D12 -> 251.78472 | P52: =P42 -> 32768 | Q52: =Q42 -> 4096 | R52: =R42 -> 512 | S52: =S42 -> 64 | T52: =T42 -> 8 | U52: =U42 -> 1 | X52: =B11 -> 7 | Y52: =IF(X52="","",$Y$37*(X52^6)+$Y$38*(X52^5)+$Y$39*(X52^4)+$Y$40*(X52^3)+$Y$41*(X52^2)+$Y$42*(X52^1)+$Y$43) -> 283.32174 | AA52: 7 | AB52: =F12 -> 22.039555 | AC52: =AC42 -> 0.27376832 | AD52: =AD42 -> 0.35473705 | AE52: =AE42 -> 0.4596528 | AF52: =AF42 -> 0.59559806 | AG52: =AG42 -> 0.77175 | AH52: =AH42 -> 1 | AK52: =C11 -> 0.68404 | AL52: =IF(AK52="","",$AL$37*(AK52^6)+$AL$38*(AK52^5)+$AL$39*(AK52^4)+$AL$40*(AK52^3)+$AL$41*(AK52^2)+$AL$42*(AK52^1)+$AL$43) -> 26.2227 | AN52: 7 | AO52: =C12 -> 0.77175 | AP52: =AP42 -> 5200128.9 | AQ52: =AQ42 -> 235945.28 | AR52: =AR42 -> 10705.537 | AS52: =AS42 -> 485.74198 | AT52: =AT42 -> 22.039555 | AU52: =AU42 -> 1 | AX52: =F11 -> 26.2227 | AY52: =IF(AX52="","",$AY$37*(AX52^6)+$AY$38*(AX52^5)+$AY$39*(AX52^4)+$AY$40*(AX52^3)+$AY$41*(AX52^2)+$AY$42*(AX52^1)+$AY$43) -> 0.68404 | BA52: 7 | BB52: =G12 -> 11.42422 | BC52: =BC42 -> 32768 | BD52: =BD42 -> 4096 | BE52: =BE42 -> 512 | BF52: =BF42 -> 64 | BG52: =BG42 -> 8 | BH52: =BH42 -> 1 | BK52: =B11 -> 7 | BL52: =IF(BK52="","",$BL$37*(BK52^6)+$BL$38*(BK52^5)+$BL$39*(BK52^4)+$BL$40*(BK52^3)+$BL$41*(BK52^2)+$BL$42*(BK52^1)+$BL$43) -> 10.804446
A53: 8 | B53: =B13 -> 9 | C53: =C43 -> 0.51909346 | D53: =D43 -> 0.59182928 | E53: =E43 -> 0.6747569 | F53: =F43 -> 0.76930441 | G53: =G43 -> 0.8771 | H53: =H43 -> 1 | K53: =C12 -> 0.77175 | L53: =IF(K53="","",$L$37*(K53^6)+$L$38*(K53^5)+$L$39*(K53^4)+$L$40*(K53^3)+$L$41*(K53^2)+$L$42*(K53^1)+$L$43) -> 8 | N53: 8 | O53: =D13 -> 226.19792 | P53: =P43 -> 59049 | Q53: =Q43 -> 6561 | R53: =R43 -> 729 | S53: =S43 -> 81 | T53: =T43 -> 9 | U53: =U43 -> 1 | X53: =B12 -> 8 | Y53: =IF(X53="","",$Y$37*(X53^6)+$Y$38*(X53^5)+$Y$39*(X53^4)+$Y$40*(X53^3)+$Y$41*(X53^2)+$Y$42*(X53^1)+$Y$43) -> 251.78472 | AA53: 8 | AB53: =F13 -> 14.9844 | AC53: =AC43 -> 0.51909346 | AD53: =AD43 -> 0.59182928 | AE53: =AE43 -> 0.6747569 | AF53: =AF43 -> 0.76930441 | AG53: =AG43 -> 0.8771 | AH53: =AH43 -> 1 | AK53: =C12 -> 0.77175 | AL53: =IF(AK53="","",$AL$37*(AK53^6)+$AL$38*(AK53^5)+$AL$39*(AK53^4)+$AL$40*(AK53^3)+$AL$41*(AK53^2)+$AL$42*(AK53^1)+$AL$43) -> 22.039555 | AN53: 8 | AO53: =C13 -> 0.8771 | AP53: =AP43 -> 755434.45 | AQ53: =AQ43 -> 50414.728 | AR53: =AR43 -> 3364.4809 | AS53: =AS43 -> 224.53224 | AT53: =AT43 -> 14.9844 | AU53: =AU43 -> 1 | AX53: =F12 -> 22.039555 | AY53: =IF(AX53="","",$AY$37*(AX53^6)+$AY$38*(AX53^5)+$AY$39*(AX53^4)+$AY$40*(AX53^3)+$AY$41*(AX53^2)+$AY$42*(AX53^1)+$AY$43) -> 0.77175 | BA53: 8 | BB53: =G13 -> 15.09556 | BC53: =BC43 -> 59049 | BD53: =BD43 -> 6561 | BE53: =BE43 -> 729 | BF53: =BF43 -> 81 | BG53: =BG43 -> 9 | BH53: =BH43 -> 1 | BK53: =B12 -> 8 | BL53: =IF(BK53="","",$BL$37*(BK53^6)+$BL$38*(BK53^5)+$BL$39*(BK53^4)+$BL$40*(BK53^3)+$BL$41*(BK53^2)+$BL$42*(BK53^1)+$BL$43) -> 11.42422
K54: =C13 -> 0.8771 | L54: =IF(K54="","",$L$37*(K54^6)+$L$38*(K54^5)+$L$39*(K54^4)+$L$40*(K54^3)+$L$41*(K54^2)+$L$42*(K54^1)+$L$43) -> 9 | X54: =B13 -> 9 | Y54: =IF(X54="","",$Y$37*(X54^6)+$Y$38*(X54^5)+$Y$39*(X54^4)+$Y$40*(X54^3)+$Y$41*(X54^2)+$Y$42*(X54^1)+$Y$43) -> 226.19792 | AK54: =C13 -> 0.8771 | AL54: =IF(AK54="","",$AL$37*(AK54^6)+$AL$38*(AK54^5)+$AL$39*(AK54^4)+$AL$40*(AK54^3)+$AL$41*(AK54^2)+$AL$42*(AK54^1)+$AL$43) -> 14.9844 | AX54: =F13 -> 14.9844 | AY54: =IF(AX54="","",$AY$37*(AX54^6)+$AY$38*(AX54^5)+$AY$39*(AX54^4)+$AY$40*(AX54^3)+$AY$41*(AX54^2)+$AY$42*(AX54^1)+$AY$43) -> 0.8771 | BK54: =B13 -> 9 | BL54: =IF(BK54="","",$BL$37*(BK54^6)+$BL$38*(BK54^5)+$BL$39*(BK54^4)+$BL$40*(BK54^3)+$BL$41*(BK54^2)+$BL$42*(BK54^1)+$BL$43) -> 15.095561
A55: m\x^n | B55: 6 | C55: 5 | D55: 4 | E55: 3 | F55: 2 | G55: 1 | H55: 0 | N55: m\x^n | O55: 6 | P55: 5 | Q55: 4 | R55: 3 | S55: 2 | T55: 1 | U55: 0 | AA55: m\x^n | AB55: 6 | AC55: 5 | AD55: 4 | AE55: 3 | AF55: 2 | AG55: 1 | AH55: 0 | AN55: m\x^n | AO55: 6 | AP55: 5 | AQ55: 4 | AR55: 3 | AS55: 2 | AT55: 1 | AU55: 0 | BA55: m\x^n | BB55: 6 | BC55: 5 | BD55: 4 | BE55: 3 | BF55: 2 | BG55: 1 | BH55: 0
A56: 2 | B56: =B37 -> 0.0015733738 | C56: =B47 -> 3 | D56: =D47 -> 0.013527616 | E56: =E47 -> 0.039665776 | F56: =F47 -> 0.11630828 | G56: =G47 -> 0.34104 | H56: =H47 -> 1 | I56: =IF($B$4=7,MDETERM(B56:H62),IF($B$4=6,MDETERM(C56:H61),IF($B$4=5,MDETERM(D56:H60),IF($B$4=4,MDETERM(E56:H59),IF($B$4=3,MDETERM(F56:H58),"ERRO"))))) -> 3.7162357e-11 | K56: Montagem Curva | N56: 2 | O56: =O37 -> 729 | P56: =O47 -> 566.77141 | Q56: =Q47 -> 81 | R56: =R47 -> 27 | S56: =S47 -> 9 | T56: =T47 -> 3 | U56: =U47 -> 1 | V56: =IF($B$4=7,MDETERM(O56:U62),IF($B$4=6,MDETERM(P56:U61),IF($B$4=5,MDETERM(Q56:U60),IF($B$4=4,MDETERM(R56:U59),IF($B$4=3,MDETERM(S56:U58),"ERRO"))))) -> 14869196 | X56: Montagem Curva | AA56: 2 | AB56: =AB37 -> 0.0015733738 | AC56: =AB47 -> 66.1811 | AD56: =AD47 -> 0.013527616 | AE56: =AE47 -> 0.039665776 | AF56: =AF47 -> 0.11630828 | AG56: =AG47 -> 0.34104 | AH56: =AH47 -> 1 | AI56: =IF($B$4=7,MDETERM(AB56:AH62),IF($B$4=6,MDETERM(AC56:AH61),IF($B$4=5,MDETERM(AD56:AH60),IF($B$4=4,MDETERM(AE56:AH59),IF($B$4=3,MDETERM(AF56:AH58),"ERRO"))))) -> 1.797128e-09 | AK56: Montagem Curva | AN56: 2 | AO56: =AO37 -> 8.4024104e+10 | AP56: =AO47 -> 0.34104 | AQ56: =AQ47 -> 19183857 | AR56: =AR47 -> 289869.11 | AS56: =AS47 -> 4379.938 | AT56: =AT47 -> 66.1811 | AU56: =AU47 -> 1 | AV56: =IF($B$4=7,MDETERM(AO56:AU62),IF($B$4=6,MDETERM(AP56:AU61),IF($B$4=5,MDETERM(AQ56:AU60),IF($B$4=4,MDETERM(AR56:AU59),IF($B$4=3,MDETERM(AS56:AU58),"ERRO"))))) -> -3.832216e+19 | AX56: Montagem Curva | BA56: 2 | BB56: =BB37 -> 729 | BC56: =BB47 -> 8.5639466 | BD56: =BD47 -> 81 | BE56: =BE47 -> 27 | BF56: =BF47 -> 9 | BG56: =BG47 -> 3 | BH56: =BH47 -> 1 | BI56: =IF($B$4=7,MDETERM(BB56:BH62),IF($B$4=6,MDETERM(BC56:BH61),IF($B$4=5,MDETERM(BD56:BH60),IF($B$4=4,MDETERM(BE56:BH59),IF($B$4=3,MDETERM(BF56:BH58),"ERRO"))))) -> -26944547 | BK56: Montagem Curva
